<?xml version="1.0"?>
<robot name="argus" xmlns:xacro="http://www.ros.org/wiki/xacro">

  <!-- ############ MATERIALS ############ -->
  <material name="blue">
    <color rgba="0.0 0.0 0.8 1.0"/>
  </material>
  <material name="grey">
    <color rgba="0.5 0.5 0.5 1.0"/>
  </material>

  <!-- ############ WHEEL MACRO ############ -->
  <xacro:property name="wheel_radius" value="0.05" />
  <xacro:property name="wheel_height" value="0.04" />
  <xacro:property name="wheel_mass" value="0.5" />

  <xacro:macro name="wheel" params="prefix parent">
    <link name="${prefix}_wheel_link">
      <visual>
        <geometry>
          <cylinder radius="${wheel_radius}" length="${wheel_height}"/>
        </geometry>
        <material name="grey"/>
      </visual>
      <collision>
        <geometry>
          <cylinder radius="${wheel_radius}" length="${wheel_height}"/>
        </geometry>
      </collision>
      <inertial>
        <mass value="${wheel_mass}"/>
        <inertia ixx="0.001" ixy="0.0" ixz="0.0" iyy="0.001" iyz="0.0" izz="0.001"/>
      </inertial>
    </link>

    <joint name="${prefix}_wheel_joint" type="continuous">
      <parent link="${parent}"/>
      <child link="${prefix}_wheel_link"/>
      <origin xyz="0 0 0" rpy="-1.5707 0 0"/>
      <axis xyz="0 0 1"/>
    </joint>

    <gazebo reference="${prefix}_wheel_link">
      <material>Gazebo/Grey</material>
    </gazebo>
  </xacro:macro>

  <!-- ############ ROBOT BODY (BASE LINK) ############ -->
  <link name="base_link">
    <visual>
      <geometry>
        <box size="0.5 0.3 0.1"/>
      </geometry>
      <material name="blue"/>
    </visual>
    <collision>
      <geometry>
        <box size="0.5 0.3 0.1"/>
      </geometry>
    </collision>
    <inertial>
      <mass value="5.0"/>
      <inertia ixx="0.01" ixy="0.0" ixz="0.0" iyy="0.01" iyz="0.0" izz="0.01"/>
    </inertial>
  </link>

  <gazebo reference="base_link">
    <material>Gazebo/Blue</material>
  </gazebo>

  <!-- ############ WHEEL MOUNTS ############ -->
  <link name="front_left_mount"/>
  <link name="front_right_mount"/>
  <link name="rear_left_mount"/>
  <link name="rear_right_mount"/>

  <joint name="front_left_mount_joint" type="fixed"><parent link="base_link"/><child link="front_left_mount"/><origin xyz="0.15 0.17 0"/></joint>
  <joint name="front_right_mount_joint" type="fixed"><parent link="base_link"/><child link="front_right_mount"/><origin xyz="0.15 -0.17 0"/></joint>
  <joint name="rear_left_mount_joint" type="fixed"><parent link="base_link"/><child link="rear_left_mount"/><origin xyz="-0.15 0.17 0"/></joint>
  <joint name="rear_right_mount_joint" type="fixed"><parent link="base_link"/><child link="rear_right_mount"/><origin xyz="-0.15 -0.17 0"/></joint>

  <!-- Attach wheels using the macro -->
  <xacro:wheel prefix="front_left" parent="front_left_mount"/>
  <xacro:wheel prefix="front_right" parent="front_right_mount"/>
  <xacro:wheel prefix="rear_left" parent="rear_left_mount"/>
  <xacro:wheel prefix="rear_right" parent="rear_right_mount"/>

  <!-- ############ LIDAR SENSOR ############ -->
  <link name="laser_link">
    <visual>
      <geometry>
        <cylinder radius="0.03" length="0.05"/>
      </geometry>
      <material name="grey"/>
    </visual>
    <collision>
      <geometry>
        <cylinder radius="0.03" length="0.05"/>
      </geometry>
    </collision>
    <inertial>
      <mass value="0.1"/>
      <inertia ixx="0.0001" ixy="0.0" ixz="0.0" iyy="0.0001" iyz="0.0" izz="0.0001"/>
    </inertial>
  </link>

  <joint name="laser_joint" type="fixed">
    <parent link="base_link"/>
    <child link="laser_link"/>
    <origin xyz="0.2 0 0.1" rpy="0 0 0"/>
  </joint>

  <!-- ############ GAZEBO PLUGINS ############ -->
  <gazebo>
    <!-- Differential Drive Controller -->
    <plugin name="diff_drive_controller" filename="libgazebo_ros_diff_drive.so">
      <rosNamespace>/argus</rosNamespace>
      <commandTopic>cmd_vel</commandTopic>
      <odometryTopic>odom</odometryTopic>
      <odometryFrame>odom</odometryFrame>
      <robotBaseFrame>base_link</robotBaseFrame>

      <!-- This is the critical line that fixes the RobotModel error in RViz -->
      <publishWheelJointState>true</publishWheelJointState>

      <leftJoint>front_left_wheel_joint</leftJoint>
      <leftJoint>rear_left_wheel_joint</leftJoint>
      <rightJoint>front_right_wheel_joint</rightJoint>
      <rightJoint>rear_right_wheel_joint</rightJoint>

      <wheelSeparation>0.34</wheelSeparation>
      <wheelDiameter>0.1</wheelDiameter>
      <maxWheelTorque>20</maxWheelTorque>
      <maxWheelAcceleration>1.0</maxWheelAcceleration>

      <publishOdom>true</publishOdom>
      <publishOdomTF>true</publishOdomTF>
      <publishWheelTF>false</publishWheelTF>
    </plugin>
  </gazebo>

  <gazebo reference="laser_link">
    <!-- LiDAR Sensor Plugin -->
    <sensor type="ray" name="head_hokuyo_sensor">
      <pose>0 0 0 0 0 0</pose>
      <visualize>true</visualize>
      <update_rate>20</update_rate>
      <ray>
        <scan>
          <horizontal>
            <samples>720</samples>
            <resolution>1</resolution>
            <min_angle>-1.5708</min_angle>
            <max_angle>1.5708</max_angle>
          </horizontal>
        </scan>
        <range>
          <min>0.10</min>
          <max>10.0</max>
          <resolution>0.01</resolution>
        </range>
      </ray>
      <plugin name="gazebo_ros_head_hokuyo_controller" filename="libgazebo_ros_laser.so">
        <topicName>/argus/scan</topicName>
        <frameName>laser_link</frameName>
      </plugin>
    </sensor>
  </gazebo>

</robot>
